#VRML_SIM R2023b utf8
# license: Apache License 2.0
# license url: http://www.apache.org/licenses/LICENSE-2.0
# This is a proto file for Webots for the eduro
# Extracted from: /mnt/c/Users/emman/Desktop/PFE_Mastech/code/urdf/eduro_description/urdf/eduro_description.urdf

PROTO Eduro [
  field  SFVec3f     translation     0 0 0
  field  SFRotation  rotation        0 0 1 0
  field  SFString    name            "Eduro"  # Is `Robot.name`.
  field  SFString    controller      "<extern>"   # Utilisation d'un contrôleur externe.
  field  MFString    controllerArgs  []       # Is `Robot.controllerArgs`.
  field  SFString    customData      ""       # Is `Robot.customData`.
  field  SFBool      supervisor      FALSE    # Is `Robot.supervisor`.
  field  SFBool      synchronization TRUE     # Is `Robot.synchronization`.
  field  SFBool      selfCollision   FALSE    # Is `Robot.selfCollision`.

]
{
  Robot {
    translation IS translation
    rotation IS rotation
    name IS name
    controller IS controller
    controllerArgs IS controllerArgs
    customData IS customData
    supervisor IS supervisor
    synchronization IS synchronization
    selfCollision IS selfCollision
    children [
      Solid {
        translation -0.052396 -0.0000 0.118859
        children [
          Shape {
            appearance DEF base_Link_material PBRAppearance {
              roughness 1.000000
              metalness 0
            }
            geometry DEF base_Link Mesh {
              url "../protos/meshes/base_Link.STL" 
            }
            castShadows FALSE
          }
          HingeJoint {
            jointParameters HingeJointParameters {
              axis 0.000000 1.000000 0.000000
              anchor 0.052396 -0.20577 -0.0445
            }
            device [
              RotationalMotor {
                name "right_wheel_joint"
                maxTorque 10000
              }
              PositionSensor {
                name "right_wheel_joint_sensor"
              }
            ]
            endPoint Solid {
              translation 0.052396 -0.20577 -0.0445
              rotation 1 0 0 1.5708  # Rotation pour aligner le cylindre correctement
              children [
                Shape {
                  appearance DEF right_wheel_Link_material PBRAppearance {
                    baseColor 0.0 0.0 0.0  # Noir
                    roughness 1.000000
                    metalness 0
                  }
                  geometry Cylinder {
                    height 0.03
                    radius 0.0762
                  }
                }
              ]
              name "right_wheel_Link"
              contactMaterial "wheel"
              boundingObject Cylinder{
                  height 0.03
                  radius 0.0762
              }
              physics Physics {
                density -1
                mass 1
                centerOfMass [ 0.000000 0.000000 0.000000 ]
                inertiaMatrix [
                  6.489000e-04 1.271000e-03 6.489000e-04
                  0.000000e+00 0.000000e+00 0.000000e+00
                ]
              }
            }
          }
          HingeJoint {
            jointParameters HingeJointParameters {
              axis 0.000000 1.000000 0.000000
              anchor 0.052396 0.20577 -0.0445
            }
            device [
              RotationalMotor {
                name "left_wheel_joint"
                maxTorque 10000
              }
              PositionSensor {
                name "left_wheel_joint_sensor"
              }
            ]
            endPoint Solid {
              translation 0.052396 0.20576 -0.0445
              rotation 1 0 0 1.5708  # Rotation pour aligner le cylindre correctement
              children [
                Shape {
                  appearance DEF left_wheel_Link_material PBRAppearance {
                    baseColor 0.0 0.0 0.0  # Noir
                    roughness 1.000000
                    metalness 0
                  }
                  geometry Cylinder {
                   height 0.03
                   radius 0.0762
                  }
                }
              ]
              name "left_wheel_Link"
              contactMaterial "wheel"
              boundingObject Cylinder{
                  height 0.03
                  radius 0.0762
              }
              physics Physics {
                density -1
                mass 1
                centerOfMass [ 0.000000 0.000000 0.000000 ]
                inertiaMatrix [
                  6.489000e-04 1.271000e-03 6.489000e-04
                  0.000000e+00 0.000000e+00 0.000000e+00
                ]
              }
            }
          }
          HingeJoint {
            jointParameters HingeJointParameters {
              axis 0.000000 0.000000 1.000000
              anchor -0.225230 0.000015 -0.059419
            }
            endPoint Solid {
              translation -0.225230 0.000015 -0.059419
              children [
                Shape {
                  appearance DEF caster_wheel_Link1_material PBRAppearance {
                    roughness 1.000000
                    metalness 0
                  }
                  geometry DEF caster_wheel_Link1 Mesh {
                    url "../protos/meshes/caster_wheel_Link1.STL"
                  }
                }
                HingeJoint {
                  jointParameters HingeJointParameters {
                    axis 0.000000 1.000000 0.000000
                    anchor -0.021379 0.000000 -0.034440
                  }
                  endPoint Solid {
                    translation -0.021379 0.000000 -0.034440
                    rotation 1 0 0 1.5708  # Rotation pour aligner le cylindre correctement
                    children [
                      Shape {
                        appearance DEF caster_wheel_Link2_material PBRAppearance {
                          baseColor 0.0 0.0 0.0  # Noir
                          roughness 1.000000
                          metalness 0
                        }
                        geometry Cylinder {
                          height 0.02
                          radius 0.025
                        }
                      }
                    ]
                    name "caster_wheel_Link2"
                    contactMaterial "wheel"
                    boundingObject Cylinder{
                        height 0.02
                        radius 0.025
                    }
                    physics Physics {
                      density -1
                      mass 1
                      centerOfMass [ 0.000000 0.000000 0.000000 ]
                      inertiaMatrix [
                        7.443600e-06 1.279500e-05 7.443600e-06
                        0.000000e+00 0.000000e+00 0.000000e+00
                      ]
                    }
                  }
                }
              ]
              name "caster_wheel_Link1"
              boundingObject USE caster_wheel_Link1
              physics Physics {
                density -1
                mass 0.158750
                centerOfMass [ 0.000000 0.000000 0.000000 ]
                inertiaMatrix [
                  4.830000e-05 5.217000e-05 4.294000e-05
                  0.000000e+00 0.000000e+00 0.000000e+00
                ]
              }
            }
          }
          Solid {
            translation 0.215034 0.017516 0.126428
            children [
              Shape {
                appearance DEF camera_Link_material PBRAppearance {
                 roughness 1.000000
                 metalness 0
                }
               geometry DEF camera_Link Mesh {
                 url "../protos/meshes/camera_Link.STL"
               }
              }
              Camera {
                name "rgb_camera"
                fieldOfView 1.212
                width 640
                height 480
                near 0.01
                far 10.0
              }
              RangeFinder {
                name "depth_camera"
                fieldOfView 1.518
                width 640
                height 480
                near 0.01
               }
            ]
            name "camera_Link"
            boundingObject USE camera_Link
            physics Physics {
              density -1
              mass 0.076213
              centerOfMass [ -0.033493 -0.017500 -0.005228 ]
              inertiaMatrix [
                5.770400e-05 7.447800e-06 5.985000e-05
                6.882900e-20 -3.391000e-07 1.052500e-19
              ]
            }
          }
          Solid {
            translation 0.251326 0.0000 0.092712
            children [
              Shape {
                appearance DEF Lidar_Link_material PBRAppearance {
                  roughness 1.000000
                  metalness 0
                }
                geometry DEF Lidar_Link Mesh {
                  url "../protos/meshes/Lidar_Link.STL"
                }
                castShadows FALSE
              }
              Lidar {
                name "lidar"
                horizontalResolution 360
                numberOfLayers 1
                fieldOfView 3.14 # seulement 180 degrees
                minRange 0.15
                maxRange 8
                resolution 0.01
              }
            ]
            name "Lidar_Link"
            boundingObject USE Lidar_Link
            physics Physics {
              density -1
              mass 0.233320
              centerOfMass [ -0.013504 -0.000508 -0.006245 ]
              inertiaMatrix [
                9.983200e-05 1.620900e-04 2.468700e-04
                -1.496900e-06 1.273900e-05 -8.085400e-08
              ]
            }
          }
        ]
        name "base_Link"
        boundingObject USE base_Link
        physics Physics {
          density -1
          mass 1
          centerOfMass [ 0.000000 0.000000 0.000000 ]
          inertiaMatrix [
            1.814242e-01 2.078845e-01 2.958210e-01
            -2.844000e-04 -5.577630e-03 -4.221000e-05
          ]
        }
      }
    ]
   # boundingObject USE foot_print_link
    physics Physics {
      density -1
      mass 1
      centerOfMass [ -0.038832 -0.000017 0.117505 ]
      inertiaMatrix [
        2.162537e-01 2.629741e-01 3.710457e-01
        2.987100e-04 1.626499e-03 4.181918e-05
      ]
    }

  }
}
